<?xml version="1.0" encoding="utf-8"?>
<robot name="fetch" path="fetch.urdf">
	<link name="base_link">
		<inertial>
			<origin rpy="0 0 0" xyz="-0.0036 0.0 0.0014"></origin>
			<mass value="70.1294"></mass>
			<inertia ixx="1.225" ixy="0.0099" ixz="0.0062" iyy="1.2853" iyz="-0.0034" izz="0.987"></inertia>
		</inertial>
		<visual>
			<origin rpy="0 0 0" xyz="0 0 0"></origin>
			<geometry>
				<mesh filename="package://meshes/base_link.dae"></mesh>
			</geometry>
			<material name="">
				<color rgba="0.356 0.361 0.376 1"></color>
			</material>
		</visual>
		<collision>
			<geometry>
				<sphere radius="0.3592124283313751"></sphere>
			</geometry>
			<origin xyz="-0.021129071712493896 -0.00949883833527565 0.2043241709470749" rpy="0 0 0"></origin>
		</collision>
	</link>
	<link name="torso_lift_link">
		<inertial>
			<origin rpy="0 0 0" xyz="-0.0013 -0.0009 0.2935"></origin>
			<mass value="10.7796"></mass>
			<inertia ixx="0.3354" ixy="0.0" ixz="-0.0162" iyy="0.3354" iyz="-0.0006" izz="0.0954"></inertia>
		</inertial>
		<visual>
			<origin rpy="0 0 0" xyz="0 0 0"></origin>
			<geometry>
				<mesh filename="package://meshes/torso_lift_link.dae"></mesh>
			</geometry>
			<material name="">
				<color rgba="1 1 1 1"></color>
			</material>
		</visual>
		<collision>
			<geometry>
				<sphere radius="0.34423375129699707"></sphere>
			</geometry>
			<origin xyz="-0.056454848498106 0.006832123268395662 0.32789692282676697" rpy="0 0 0"></origin>
		</collision>
	</link>
	<link name="torso_lift_link_collision_2">
		<visual>
			<geometry>
				<sphere radius="0.0001"></sphere>
			</geometry>
		</visual>
	</link>
	<link name="head_pan_link">
		<inertial>
			<origin rpy="0 0 0" xyz="0.0321 0.0161 0.0390"></origin>
			<mass value="2.2556"></mass>
			<inertia ixx="0.0129" ixy="0.0002" ixz="0.0007" iyy="0.0095" iyz="-0.0" izz="0.0184"></inertia>
		</inertial>
		<visual>
			<origin rpy="0 0 0" xyz="0 0 0"></origin>
			<geometry>
				<mesh filename="package://meshes/head_pan_link.dae"></mesh>
			</geometry>
			<material name="">
				<color rgba="0.356 0.361 0.376 1"></color>
			</material>
		</visual>
	</link>
	<link name="head_tilt_link">
		<inertial>
			<origin rpy="0 0 0" xyz="0.0081 0.0025 0.0113"></origin>
			<mass value="0.9087"></mass>
			<inertia ixx="0.0061" ixy="-0.0" ixz="0.0002" iyy="0.0014" iyz="-0.0001" izz="0.0061"></inertia>
		</inertial>
		<visual>
			<origin rpy="0 0 0" xyz="0 0 0"></origin>
			<geometry>
				<mesh filename="package://meshes/head_tilt_link.dae"></mesh>
			</geometry>
			<material name="">
				<color rgba="0.086 0.506 0.767 1"></color>
			</material>
		</visual>
	</link>
	<link name="shoulder_pan_link">
		<inertial>
			<origin rpy="0 0 0" xyz="0.0927 -0.0056 0.0564"></origin>
			<mass value="2.5587"></mass>
			<inertia ixx="0.0043" ixy="-0.0001" ixz="0.001" iyy="0.0087" iyz="-0.0001" izz="0.0087"></inertia>
		</inertial>
		<visual>
			<origin rpy="0 0 0" xyz="0 0 0"></origin>
			<geometry>
				<mesh filename="package://meshes/shoulder_pan_link.dae"></mesh>
			</geometry>
			<material name="">
				<color rgba="1 1 1 1"></color>
			</material>
		</visual>
		<collision>
			<geometry>
				<sphere radius="0.14189939200878143"></sphere>
			</geometry>
			<origin xyz="0.05012618005275726 -0.018745532259345055 0.022201823070645332" rpy="0 0 0"></origin>
		</collision>
	</link>
	<link name="shoulder_lift_link">
		<inertial>
			<origin rpy="0 0 0" xyz="0.1432 0.0072 -0.0001"></origin>
			<mass value="2.6615"></mass>
			<inertia ixx="0.0028" ixy="-0.0021" ixz="-0.0" iyy="0.0111" iyz="-0.0" izz="0.0112"></inertia>
		</inertial>
		<visual>
			<origin rpy="0 0 0" xyz="0 0 0"></origin>
			<geometry>
				<mesh filename="package://meshes/shoulder_lift_link.dae"></mesh>
			</geometry>
			<material name="">
				<color rgba="0.086 0.506 0.767 1"></color>
			</material>
		</visual>
		<collision>
			<geometry>
				<sphere radius="0.13528214395046234"></sphere>
			</geometry>
			<origin xyz="0.06818880885839462 0.007007176987826824 -0.0011842577951028943" rpy="0 0 0"></origin>
		</collision>
	</link>
	<link name="upperarm_roll_link">
		<inertial>
			<origin rpy="0 0 0" xyz="0.1165 0.0014 0.0000"></origin>
			<mass value="2.3311"></mass>
			<inertia ixx="0.0019" ixy="-0.0001" ixz="0.0" iyy="0.0045" iyz="0.0" izz="0.0047"></inertia>
		</inertial>
		<visual>
			<origin rpy="0 0 0" xyz="0 0 0"></origin>
			<geometry>
				<mesh filename="package://meshes/upperarm_roll_link.dae"></mesh>
			</geometry>
			<material name="">
				<color rgba="1 1 1 1"></color>
			</material>
		</visual>
		<collision>
			<geometry>
				<sphere radius="0.13586905598640442"></sphere>
			</geometry>
			<origin xyz="0.07358336448669434 -0.015587449073791504 -6.987340748310089e-05" rpy="0 0 0"></origin>
		</collision>
	</link>
	<link name="elbow_flex_link">
		<inertial>
			<origin rpy="0 0 0" xyz="0.1279 0.0073 0.0000"></origin>
			<mass value="2.1299"></mass>
			<inertia ixx="0.0024" ixy="-0.0016" ixz="0.0" iyy="0.0082" iyz="-0.0" izz="0.0084"></inertia>
		</inertial>
		<visual>
			<origin rpy="0 0 0" xyz="0 0 0"></origin>
			<geometry>
				<mesh filename="package://meshes/elbow_flex_link.dae"></mesh>
			</geometry>
			<material name="">
				<color rgba="0.086 0.506 0.767 1"></color>
			</material>
		</visual>
		<collision>
			<geometry>
				<sphere radius="0.12813588976860046"></sphere>
			</geometry>
			<origin xyz="0.052882369607686996 0.016472242772579193 -0.0009001107537187636" rpy="0 0 0"></origin>
		</collision>
	</link>
	<link name="forearm_roll_link">
		<inertial>
			<origin rpy="0 0 0" xyz="0.1097 -0.0266 0.0000"></origin>
			<mass value="1.6563"></mass>
			<inertia ixx="0.0016" ixy="-0.0003" ixz="0.0" iyy="0.003" iyz="-0.0" izz="0.0035"></inertia>
		</inertial>
		<visual>
			<origin rpy="0 0 0" xyz="0 0 0"></origin>
			<geometry>
				<mesh filename="package://meshes/forearm_roll_link.dae"></mesh>
			</geometry>
			<material name="">
				<color rgba="1 1 1 1"></color>
			</material>
		</visual>
		<collision>
			<geometry>
				<sphere radius="0.12434487789869308"></sphere>
			</geometry>
			<origin xyz="0.07074487209320068 -0.029582727700471878 0.0007163408445194364" rpy="0 0 0"></origin>
		</collision>
	</link>
	<link name="wrist_flex_link">
		<inertial>
			<origin rpy="0 0 0" xyz="0.0882 0.0009 -0.0001"></origin>
			<mass value="1.725"></mass>
			<inertia ixx="0.0018" ixy="-0.0001" ixz="-0.0" iyy="0.0042" iyz="0.0" izz="0.0042"></inertia>
		</inertial>
		<visual>
			<origin rpy="0 0 0" xyz="0 0 0"></origin>
			<geometry>
				<mesh filename="package://meshes/wrist_flex_link.dae"></mesh>
			</geometry>
			<material name="">
				<color rgba="0.086 0.506 0.767 1"></color>
			</material>
		</visual>
		<collision>
			<geometry>
				<sphere radius="0.10675159841775894"></sphere>
			</geometry>
			<origin xyz="0.026737522333860397 0.009181365370750427 -0.0012763678096234798" rpy="0 0 0"></origin>
		</collision>
	</link>
	<link name="wrist_roll_link">
		<inertial>
			<origin rpy="0 0 0" xyz="0.0095 0.0004 -0.0002"></origin>
			<mass value="0.1354"></mass>
			<inertia ixx="0.0001" ixy="0.0" ixz="0.0" iyy="0.0001" iyz="0.0" izz="0.0001"></inertia>
		</inertial>
		<visual>
			<origin rpy="0 0 0" xyz="0 0 0"></origin>
			<geometry>
				<mesh filename="package://meshes/wrist_roll_link.dae"></mesh>
			</geometry>
			<material name="">
				<color rgba="1 1 1 1"></color>
			</material>
		</visual>
		<collision>
			<geometry>
				<sphere radius="0.06033722311258316"></sphere>
			</geometry>
			<origin xyz="-0.00962600577622652 7.77833120082505e-05 -0.003384500741958618" rpy="0 0 0"></origin>
		</collision>
	</link>
	<link name="gripper_link">
		<inertial>
			<origin rpy="0 0 0" xyz="-0.0900 -0.0001 -0.0017"></origin>
			<mass value="1.5175"></mass>
			<inertia ixx="0.0013" ixy="-0.0" ixz="0.0" iyy="0.0019" iyz="-0.0" izz="0.0024"></inertia>
		</inertial>
		<visual>
			<origin rpy="0 0 0" xyz="0 0 0"></origin>
			<geometry>
				<mesh filename="package://meshes/gripper_link.dae"></mesh>
			</geometry>
		</visual>
		<collision>
			<geometry>
				<sphere radius="0.09044913202524185"></sphere>
			</geometry>
			<origin xyz="-0.08851374685764313 0.004671198315918446 -8.518578397342935e-05" rpy="0 0 0"></origin>
		</collision>
	</link>
	<link name="r_gripper_finger_link">
		<inertial>
			<origin rpy="0 0 0" xyz="-0.01 0 0"></origin>
			<mass value="0.0798"></mass>
			<inertia ixx="0.002" ixy="0" ixz="0" iyy="0" iyz="0" izz="0"></inertia>
		</inertial>
		<visual>
			<origin rpy="0 0 0" xyz="0 0.101425 0"></origin>
			<geometry>
				<mesh filename="package://meshes/r_gripper_finger_link.STL"></mesh>
			</geometry>
			<material name="">
				<color rgba="0.356 0.361 0.376 1"></color>
			</material>
		</visual>
		<collision>
			<geometry>
				<sphere radius="0.03452802821993828"></sphere>
			</geometry>
			<origin xyz="0.00304347462952137 -0.00909705925732851 -0.0010664222063496709" rpy="0 0 0"></origin>
		</collision>
	</link>
	<link name="l_gripper_finger_link">
		<inertial>
			<origin rpy="0 0 0" xyz="-0.01 0 0"></origin>
			<mass value="0.0798"></mass>
			<inertia ixx="0.002" ixy="0" ixz="0" iyy="0" iyz="0" izz="0"></inertia>
		</inertial>
		<visual>
			<origin rpy="0 0 0" xyz="0 -0.101425 0"></origin>
			<geometry>
				<mesh filename="package://meshes/l_gripper_finger_link.STL"></mesh>
			</geometry>
			<material name="">
				<color rgba="0.356 0.361 0.376 1"></color>
			</material>
		</visual>
		<collision>
			<geometry>
				<sphere radius="0.019879035651683807"></sphere>
			</geometry>
			<origin xyz="-0.015466975048184395 0.009397350251674652 -0.001006869482807815" rpy="0 0 0"></origin>
		</collision>
		<collision>
			<geometry>
				<sphere radius="0.019879035651683807"></sphere>
			</geometry>
			<origin xyz="0.016500072553753853 0.00926412083208561 -0.001219027559272945" rpy="0 0 0"></origin>
		</collision>
	</link>
	<link name="bellows_link">
		<inertial>
			<origin rpy="0 0 0" xyz="0.0191320000286228 -1.67219873481315E-16 -0.134861625443387"></origin>
			<mass value="0.169374038216602"></mass>
			<inertia ixx="0.00331159128762117" ixy="-8.9230964321455E-18" ixz="-5.38622201018293E-08" iyy="0.00174447292786627" iyz="-8.06964979976371E-17" izz="0.00169417568121457"></inertia>
		</inertial>
		<visual>
			<origin rpy="0 0 0" xyz="0 0 0"></origin>
			<geometry>
				<mesh filename="package://meshes/bellows_link.STL"></mesh>
			</geometry>
			<material name="">
				<color rgba="0 0 0 1"></color>
			</material>
		</visual>
	</link>
	<link name="torso_fixed_link">
		<inertial>
			<origin rpy="0 0 0" xyz="-0.0722 0.0057 0.2656"></origin>
			<mass value="13.2775"></mass>
			<inertia ixx="0.3861" ixy="0.0015" ixz="-0.0102" iyy="0.3388" iyz="0.0117" izz="0.1018"></inertia>
		</inertial>
		<visual>
			<origin rpy="0 0 0" xyz="0 0 0"></origin>
			<geometry>
				<mesh filename="package://meshes/torso_fixed_link.dae"></mesh>
			</geometry>
			<material name="">
				<color rgba="0.086 0.506 0.767 1"></color>
			</material>
		</visual>
		<collision>
			<geometry>
				<sphere radius="0.28716233372688293"></sphere>
			</geometry>
			<origin xyz="-0.08058662712574005 0.01209321990609169 0.1929876208305359" rpy="0 0 0"></origin>
		</collision>
	</link>
	<joint name="torso_lift_collision_2_joint" type="fixed">
		<parent link="torso_lift_link"></parent>
		<child link="torso_lift_link_collision_2"></child>
	</joint>
	<joint name="torso_lift_joint" type="prismatic">
		<origin rpy="-6.123E-17 0 0" xyz="-0.086875 0 0.37743"></origin>
		<parent link="base_link"></parent>
		<child link="torso_lift_link"></child>
		<axis xyz="0 0 1"></axis>
		<limit effort="450.0" lower="0" upper="0.38615" velocity="0.1"></limit>
		<dynamics damping="100.0"></dynamics>
	</joint>
	<joint name="head_pan_joint" type="fixed">
		<origin rpy="0 0 0" xyz="0.053125 0 0.603001417713939"></origin>
		<parent link="torso_lift_link"></parent>
		<child link="head_pan_link"></child>
		<axis xyz="0 0 1"></axis>
		<limit effort="0.32" lower="-1.57" upper="1.57" velocity="1.57"></limit>
	</joint>
	<joint name="head_tilt_joint" type="fixed">
		<origin rpy="0 0 0" xyz="0.14253 0 0.057999"></origin>
		<parent link="head_pan_link"></parent>
		<child link="head_tilt_link"></child>
		<axis xyz="0 1 0"></axis>
		<limit effort="0.68" lower="-0.76" upper="1.45" velocity="1.57"></limit>
	</joint>
	<joint name="shoulder_pan_joint" type="revolute">
		<origin rpy="0 0 0" xyz="0.119525 0 0.34858"></origin>
		<parent link="torso_lift_link"></parent>
		<child link="shoulder_pan_link"></child>
		<axis xyz="0 0 1"></axis>
		<dynamics damping="1.0"></dynamics>
		<limit effort="33.82" lower="-1.6056" upper="1.6056" velocity="1.256"></limit>
	</joint>
	<joint name="shoulder_lift_joint" type="revolute">
		<origin rpy="0 0 0" xyz="0.117 0 0.0599999999999999"></origin>
		<parent link="shoulder_pan_link"></parent>
		<child link="shoulder_lift_link"></child>
		<axis xyz="0 1 0"></axis>
		<dynamics damping="1.0"></dynamics>
		<limit effort="131.76" lower="-1.221" upper="1.518" velocity="1.454"></limit>
	</joint>
	<joint name="upperarm_roll_joint" type="revolute">
		<origin rpy="0 0 0" xyz="0.219 0 0"></origin>
		<parent link="shoulder_lift_link"></parent>
		<child link="upperarm_roll_link"></child>
		<axis xyz="1 0 0"></axis>
		<dynamics damping="5.0"></dynamics>
		<limit effort="76.94" velocity="1.571" lower="-3.14159" upper="3.14159"></limit>
	</joint>
	<joint name="elbow_flex_joint" type="revolute">
		<origin rpy="0 0 0" xyz="0.133 0 0"></origin>
		<parent link="upperarm_roll_link"></parent>
		<child link="elbow_flex_link"></child>
		<axis xyz="0 1 0"></axis>
		<dynamics damping="1.0"></dynamics>
		<limit effort="66.18" lower="-2.251" upper="2.251" velocity="1.521"></limit>
	</joint>
	<joint name="forearm_roll_joint" type="revolute">
		<origin rpy="0 0 0" xyz="0.197 0 0"></origin>
		<parent link="elbow_flex_link"></parent>
		<child link="forearm_roll_link"></child>
		<axis xyz="1 0 0"></axis>
		<dynamics damping="5.0"></dynamics>
		<limit effort="29.35" velocity="1.571" lower="-3.14159" upper="3.14159"></limit>
	</joint>
	<joint name="wrist_flex_joint" type="revolute">
		<origin rpy="0 0 0" xyz="0.1245 0 0"></origin>
		<parent link="forearm_roll_link"></parent>
		<child link="wrist_flex_link"></child>
		<axis xyz="0 1 0"></axis>
		<dynamics damping="1.0"></dynamics>
		<limit effort="25.7" lower="-2.16" upper="2.16" velocity="2.268"></limit>
	</joint>
	<joint name="wrist_roll_joint" type="revolute">
		<origin rpy="0 0 0" xyz="0.1385 0 0"></origin>
		<parent link="wrist_flex_link"></parent>
		<child link="wrist_roll_link"></child>
		<axis xyz="1 0 0"></axis>
		<limit effort="7.36" velocity="2.268" lower="-3.14159" upper="3.14159"></limit>
		<dynamics damping="5.0"></dynamics>
	</joint>
	<joint name="gripper_axis" type="fixed">
		<origin rpy="0 0 0" xyz="0.16645 0 0"></origin>
		<parent link="wrist_roll_link"></parent>
		<child link="gripper_link"></child>
		<axis xyz="0 1 0"></axis>
	</joint>
	<joint name="r_gripper_finger_joint" type="fixed">
		<origin rpy="0 0 0" xyz="0 0.065425 0"></origin>
		<parent link="gripper_link"></parent>
		<child link="r_gripper_finger_link"></child>
		<axis xyz="0 1 0"></axis>
	</joint>
	<joint name="l_gripper_finger_joint" type="fixed">
		<origin rpy="0 0 0" xyz="0 -0.065425 0"></origin>
		<parent link="gripper_link"></parent>
		<child link="l_gripper_finger_link"></child>
		<axis xyz="0 -1 0"></axis>
	</joint>
	<joint name="bellows_joint" type="fixed">
		<origin rpy="0 0 0" xyz="0 0 0"></origin>
		<parent link="torso_lift_link"></parent>
		<child link="bellows_link"></child>
		<axis xyz="0 0 -1"></axis>
	</joint>
	<joint name="torso_fixed_joint" type="fixed">
		<origin rpy="-6.12303176911189E-17 0 0" xyz="-0.086875 0 0.377425"></origin>
		<parent link="base_link"></parent>
		<child link="torso_fixed_link"></child>
		<axis xyz="0 1 0"></axis>
	</joint>
</robot>