<?xml version="1.0" encoding="utf-8"?>
<robot name="ur5_robotiq85" path="ur5.urdf">
	<link name="offset_link"></link>
	<link name="base_link">
		<visual>
			<geometry>
				<mesh filename="package://meshes/ur5/visual/base.dae"></mesh>
			</geometry>
			<material name="LightGrey">
				<color rgba="0.7 0.7 0.7 1.0"></color>
			</material>
		</visual>
		<collision>
			<geometry>
				<sphere radius="0.08498566597700119"></sphere>
			</geometry>
			<origin xyz="-8.451618487015367e-05 -0.013863427564501762 0.006924038287252188" rpy="0 0 0"></origin>
		</collision>
		<inertial>
			<mass value="4.0"></mass>
			<origin rpy="0 0 0" xyz="0.0 0.0 0.0"></origin>
			<inertia ixx="0.00443333156" ixy="0.0" ixz="0.0" iyy="0.00443333156" iyz="0.0" izz="0.0072"></inertia>
		</inertial>
	</link>
	<link name="shoulder_link">
		<visual>
			<geometry>
				<mesh filename="package://meshes/ur5/visual/shoulder.dae"></mesh>
			</geometry>
			<material name="LightGrey">
				<color rgba="0.7 0.7 0.7 1.0"></color>
			</material>
		</visual>
		<collision>
			<geometry>
				<sphere radius="0.08898647874593735"></sphere>
			</geometry>
			<origin xyz="0.0013840908650308847 0.002472204389050603 -0.006471964530646801" rpy="0 0 0"></origin>
		</collision>
		<inertial>
			<mass value="3.7"></mass>
			<origin rpy="0 0 0" xyz="0.0 0.0 0.0"></origin>
			<inertia ixx="0.010267495893" ixy="0.0" ixz="0.0" iyy="0.010267495893" iyz="0.0" izz="0.00666"></inertia>
		</inertial>
	</link>
	<link name="upper_arm_link">
		<visual>
			<geometry>
				<mesh filename="package://meshes/ur5/visual/upperarm.dae"></mesh>
			</geometry>
			<material name="LightGrey">
				<color rgba="0.7 0.7 0.7 1.0"></color>
			</material>
		</visual>
		<collision>
			<geometry>
				<sphere radius="0.2760567367076874"></sphere>
			</geometry>
			<origin xyz="0.0010900379857048392 -0.004666843917220831 0.19291363656520844" rpy="0 0 0"></origin>
		</collision>
		<inertial>
			<mass value="8.393"></mass>
			<origin rpy="0 0 0" xyz="0.0 0.0 0.28"></origin>
			<inertia ixx="0.22689067591036005" ixy="0.0" ixz="0.0" iyy="0.22689067591036005" iyz="0.0" izz="0.0151074"></inertia>
		</inertial>
	</link>
	<link name="forearm_link">
		<visual>
			<geometry>
				<mesh filename="package://meshes/ur5/visual/forearm.dae"></mesh>
			</geometry>
			<material name="LightGrey">
				<color rgba="0.7 0.7 0.7 1.0"></color>
			</material>
		</visual>
		<collision>
			<geometry>
				<sphere radius="0.2431950867176056"></sphere>
			</geometry>
			<origin xyz="0.0016812300309538841 0.008153107017278671 0.17549018561840057" rpy="0 0 0"></origin>
		</collision>
		<inertial>
			<mass value="2.275"></mass>
			<origin rpy="0 0 0" xyz="0.0 0.0 0.25"></origin>
			<inertia ixx="0.04944331355599999" ixy="0.0" ixz="0.0" iyy="0.04944331355599999" iyz="0.0" izz="0.004095"></inertia>
		</inertial>
	</link>
	<link name="wrist_1_link">
		<visual>
			<geometry>
				<mesh filename="package://meshes/ur5/visual/wrist1.dae"></mesh>
			</geometry>
			<material name="LightGrey">
				<color rgba="0.7 0.7 0.7 1.0"></color>
			</material>
		</visual>
		<collision>
			<geometry>
				<sphere radius="0.062413234263658524"></sphere>
			</geometry>
			<origin xyz="-0.0005975436652079225 0.0942697748541832 -0.0017017620848491788" rpy="0 0 0"></origin>
		</collision>
		<inertial>
			<mass value="1.219"></mass>
			<origin rpy="0 0 0" xyz="0.0 0.0 0.0"></origin>
			<inertia ixx="0.11117275553087999" ixy="0.0" ixz="0.0" iyy="0.11117275553087999" iyz="0.0" izz="0.21942"></inertia>
		</inertial>
	</link>
	<link name="wrist_2_link">
		<visual>
			<geometry>
				<mesh filename="package://meshes/ur5/visual/wrist2.dae"></mesh>
			</geometry>
			<material name="LightGrey">
				<color rgba="0.7 0.7 0.7 1.0"></color>
			</material>
		</visual>
		<collision>
			<geometry>
				<sphere radius="0.06222157925367355"></sphere>
			</geometry>
			<origin xyz="0.0007823766209185123 -0.0019095134921371937 0.09571689367294312" rpy="0 0 0"></origin>
		</collision>
		<inertial>
			<mass value="1.219"></mass>
			<origin rpy="0 0 0" xyz="0.0 0.0 0.0"></origin>
			<inertia ixx="0.11117275553087999" ixy="0.0" ixz="0.0" iyy="0.11117275553087999" iyz="0.0" izz="0.21942"></inertia>
		</inertial>
	</link>
	<link name="wrist_3_link">
		<visual>
			<geometry>
				<mesh filename="package://meshes/ur5/visual/wrist3.dae"></mesh>
			</geometry>
			<material name="LightGrey">
				<color rgba="0.7 0.7 0.7 1.0"></color>
			</material>
		</visual>
		<collision>
			<geometry>
				<sphere radius="0.041476503014564514"></sphere>
			</geometry>
			<origin xyz="0.001138698193244636 0.06006338447332382 -0.001294290879741311" rpy="0 0 0"></origin>
		</collision>
		<inertial>
			<mass value="0.1879"></mass>
			<origin rpy="0 0 0" xyz="0.0 0.0 0.0"></origin>
			<inertia ixx="0.017136473145408" ixy="0.0" ixz="0.0" iyy="0.017136473145408" iyz="0.0" izz="0.033822"></inertia>
		</inertial>
	</link>
	<link name="ee_link"></link>
	<link name="tool0"></link>
	<link name="fts_robotside">
		<inertial>
			<origin rpy="0 0 0" xyz="0 0 0.01875"></origin>
			<mass value="0.65"></mass>
			<inertia ixx="0.000661171875" ixy="0" ixz="0" iyy="0.000661171875" iyz="0" izz="0.00117"></inertia>
		</inertial>
		<visual>
			<origin rpy="0 0 0" xyz="0 0 0"></origin>
			<geometry>
				<mesh filename="package://meshes/robotiq_fts300.stl"></mesh>
			</geometry>
			<material name="black"></material>
		</visual>
		<collision>
			<geometry>
				<sphere radius="0.04103250429034233"></sphere>
			</geometry>
			<origin xyz="0.0016678574029356241 -0.022652728483080864 0.0015739481896162033" rpy="0 0 0"></origin>
		</collision>
	</link>
	<link name="robotiq_force_torque_frame_id"></link>
	<link name="fts_toolside"></link>
	<link name="robotiq_85_base_link">
		<visual>
			<geometry>
				<mesh filename="package://meshes/robotiq/robotiq_85_base_link_fine.STL"></mesh>
			</geometry>
		</visual>
		<collision>
			<geometry>
				<sphere radius="0.05616769194602966"></sphere>
			</geometry>
			<origin xyz="0.0022349716164171696 0.0004417234449647367 0.04195250943303108" rpy="0 0 0"></origin>
		</collision>
		<inertial>
			<mass value="0.636951"></mass>
			<origin xyz="0.0 0.0 0.0"></origin>
			<inertia ixx="0.000380" ixy="0.000000" ixz="0.000000" iyx="0.000000" iyy="0.001110" iyz="0.000000" izx="0.000000" izy="0.000000" izz="0.001171"></inertia>
		</inertial>
	</link>
	<link name="robotiq_85_left_knuckle_link">
		<visual>
			<geometry>
				<mesh filename="meshes/robotiq/outer_knuckle_fine.STL"></mesh>
			</geometry>
		</visual>
		<collision>
			<geometry>
				<sphere radius="0.023428861051797867"></sphere>
			</geometry>
			<origin xyz="0.014739703387022018 0.00053254677914083 0.0027189692482352257" rpy="0 0 0"></origin>
		</collision>
		<inertial>
			<mass value="0.018491"></mass>
			<origin xyz="0.0 0.0 0.0"></origin>
			<inertia ixx="0.000009" ixy="-0.000001" ixz="0.000000" iyx="-0.000001" iyy="0.000001" iyz="0.000000" izx="0.000000" izy="0.000000" izz="0.000010"></inertia>
		</inertial>
	</link>
	<link name="robotiq_85_right_knuckle_link">
		<visual>
			<geometry>
				<mesh filename="meshes/robotiq/outer_knuckle_fine.STL"></mesh>
			</geometry>
		</visual>
		<collision>
			<geometry>
				<sphere radius="0.023428861051797867"></sphere>
			</geometry>
			<origin xyz="0.014739703387022018 0.00053254677914083 0.0027189692482352257" rpy="0 0 0"></origin>
		</collision>
		<inertial>
			<mass value="0.018491"></mass>
			<origin xyz="0.0 0.0 0.0"></origin>
			<inertia ixx="0.000009" ixy="-0.000001" ixz="0.000000" iyx="-0.000001" iyy="0.000001" iyz="0.000000" izx="0.000000" izy="0.000000" izz="0.000010"></inertia>
		</inertial>
	</link>
	<link name="robotiq_85_left_finger_link">
		<visual>
			<geometry>
				<mesh filename="meshes/robotiq/outer_finger_fine.STL"></mesh>
			</geometry>
		</visual>
		<collision>
			<geometry>
				<sphere radius="0.030598074197769165"></sphere>
			</geometry>
			<origin xyz="0.0015889503993093967 0.0009034458780661225 0.0260635819286108" rpy="0 0 0"></origin>
		</collision>
		<inertial>
			<mass value="0.027309"></mass>
			<origin xyz="0.0 0.0 0.0"></origin>
			<inertia ixx="0.000003" ixy="-0.000002" ixz="0.000000" iyx="-0.000002" iyy="0.000021" iyz="0.000000" izx="0.000000" izy="0.000000" izz="0.000020"></inertia>
		</inertial>
	</link>
	<link name="robotiq_85_right_finger_link">
		<visual>
			<geometry>
				<mesh filename="meshes/robotiq/outer_finger_fine.STL"></mesh>
			</geometry>
		</visual>
		<collision>
			<geometry>
				<sphere radius="0.030598074197769165"></sphere>
			</geometry>
			<origin xyz="0.0015889503993093967 0.0009034458780661225 0.0260635819286108" rpy="0 0 0"></origin>
		</collision>
		<inertial>
			<mass value="0.027309"></mass>
			<origin xyz="0.0 0.0 0.0"></origin>
			<inertia ixx="0.000003" ixy="-0.000002" ixz="0.000000" iyx="-0.000002" iyy="0.000021" iyz="0.000000" izx="0.000000" izy="0.000000" izz="0.000020"></inertia>
		</inertial>
	</link>
	<link name="robotiq_85_left_inner_knuckle_link">
		<visual>
			<geometry>
				<mesh filename="meshes/robotiq/inner_knuckle_fine.STL"></mesh>
			</geometry>
		</visual>
		<collision>
			<geometry>
				<sphere radius="0.035418976098299026"></sphere>
			</geometry>
			<origin xyz="0.015970557928085327 0.0018519113073125482 0.020829033106565475" rpy="0 0 0"></origin>
		</collision>
		<inertial>
			<mass value="0.029951"></mass>
			<origin xyz="0.0 0.0 0.0"></origin>
			<inertia ixx="0.000039" ixy="0.000000" ixz="0.000000" iyx="0.000000" iyy="0.000005" iyz="0.000000" izx="0.000000" izy="0.000000" izz="0.000035"></inertia>
		</inertial>
	</link>
	<link name="robotiq_85_right_inner_knuckle_link">
		<visual>
			<geometry>
				<mesh filename="meshes/robotiq/inner_knuckle_fine.STL"></mesh>
			</geometry>
		</visual>
		<collision>
			<geometry>
				<sphere radius="0.035418976098299026"></sphere>
			</geometry>
			<origin xyz="0.015970557928085327 0.0018519113073125482 0.020829033106565475" rpy="0 0 0"></origin>
		</collision>
		<inertial>
			<mass value="0.029951"></mass>
			<origin xyz="0.0 0.0 0.0"></origin>
			<inertia ixx="0.000039" ixy="0.000000" ixz="0.000000" iyx="0.000000" iyy="0.000005" iyz="0.000000" izx="0.000000" izy="0.000000" izz="0.000035"></inertia>
		</inertial>
	</link>
	<link name="robotiq_85_left_finger_tip_link">
		<visual>
			<geometry>
				<mesh filename="meshes/robotiq/inner_finger_fine.STL"></mesh>
			</geometry>
		</visual>
		<collision>
			<geometry>
				<sphere radius="0.030017007142305374"></sphere>
			</geometry>
			<origin xyz="0.005034731701016426 0.0006111629772931337 0.012434267438948154" rpy="0 0 0"></origin>
		</collision>
		<inertial>
			<mass value="0.019555"></mass>
			<origin xyz="0.0 0.0 0.0"></origin>
			<inertia ixx="0.000002" ixy="0.000000" ixz="0.000000" iyx="0.000000" iyy="0.000005" iyz="0.000000" izx="0.000000" izy="0.000000" izz="0.000006"></inertia>
		</inertial>
	</link>
	<link name="robotiq_85_right_finger_tip_link">
		<visual>
			<geometry>
				<mesh filename="meshes/robotiq/inner_finger_fine.STL"></mesh>
			</geometry>
		</visual>
		<collision>
			<geometry>
				<sphere radius="0.030017007142305374"></sphere>
			</geometry>
			<origin xyz="0.005034731701016426 0.0006111629772931337 0.012434267438948154" rpy="0 0 0"></origin>
		</collision>
		<inertial>
			<mass value="0.019555"></mass>
			<origin xyz="0.0 0.0 0.0"></origin>
			<inertia ixx="0.000002" ixy="0.000000" ixz="0.000000" iyx="0.000000" iyy="0.000005" iyz="0.000000" izx="0.000000" izy="0.000000" izz="0.000006"></inertia>
		</inertial>
	</link>
	<joint name="offset_joint" type="fixed">
		<parent link="offset_link"></parent>
		<child link="base_link"></child>
		<origin xyz="0.0 0.0 0.9144" rpy="0 0 1.57"></origin>
	</joint>
	<joint name="shoulder_pan_joint" type="revolute">
		<parent link="base_link"></parent>
		<child link="shoulder_link"></child>
		<origin rpy="0 0.0 0" xyz="0.0 0.0 0.089159"></origin>
		<axis xyz="0 0 1"></axis>
		<limit effort="150.0" lower="-3.14159265" upper="3.14159265" velocity="0.5"></limit>
		<dynamics damping="0.0" friction="0.0"></dynamics>
	</joint>
	<joint name="shoulder_lift_joint" type="revolute">
		<parent link="shoulder_link"></parent>
		<child link="upper_arm_link"></child>
		<origin rpy="0.0 1.570796325 0.0" xyz="0.0 0.13585 0.0"></origin>
		<axis xyz="0 1 0"></axis>
		<limit effort="150.0" lower="-3.14159265" upper="3.14159265" velocity="0.5"></limit>
		<dynamics damping="0.0" friction="0.0"></dynamics>
	</joint>
	<joint name="elbow_joint" type="revolute">
		<parent link="upper_arm_link"></parent>
		<child link="forearm_link"></child>
		<origin rpy="0.0 0.0 0.0" xyz="0.0 -0.1197 0.425"></origin>
		<axis xyz="0 1 0"></axis>
		<limit effort="150.0" lower="-3.14159265" upper="3.14159265" velocity="0.5"></limit>
		<dynamics damping="0.0" friction="0.0"></dynamics>
	</joint>
	<joint name="wrist_1_joint" type="revolute">
		<parent link="forearm_link"></parent>
		<child link="wrist_1_link"></child>
		<origin rpy="0.0 1.570796325 0.0" xyz="0.0 0.0 0.39225"></origin>
		<axis xyz="0 1 0"></axis>
		<limit effort="28.0" lower="-3.14159265" upper="3.14159265" velocity="0.5"></limit>
		<dynamics damping="0.0" friction="0.0"></dynamics>
	</joint>
	<joint name="wrist_2_joint" type="revolute">
		<parent link="wrist_1_link"></parent>
		<child link="wrist_2_link"></child>
		<origin rpy="0.0 0.0 0.0" xyz="0.0 0.093 0.0"></origin>
		<axis xyz="0 0 1"></axis>
		<limit effort="28.0" lower="-3.14159265" upper="3.14159265" velocity="0.5"></limit>
		<dynamics damping="0.0" friction="0.0"></dynamics>
	</joint>
	<joint name="wrist_3_joint" type="revolute">
		<parent link="wrist_2_link"></parent>
		<child link="wrist_3_link"></child>
		<origin rpy="0.0 0.0 0.0" xyz="0.0 0.0 0.09465"></origin>
		<axis xyz="0 1 0"></axis>
		<limit effort="28.0" lower="-3.14159265" upper="3.14159265" velocity="0.5"></limit>
		<dynamics damping="0.0" friction="0.0"></dynamics>
	</joint>
	<joint name="ee_fixed_joint" type="fixed">
		<parent link="wrist_3_link"></parent>
		<child link="ee_link"></child>
		<origin rpy="0.0 0.0 1.570796325" xyz="0.0 0.0823 0.0"></origin>
	</joint>
	<joint name="wrist_3_link-tool0_fixed_joint" type="fixed">
		<origin rpy="-1.570796325 0 0" xyz="0 0.0823 0"></origin>
		<parent link="wrist_3_link"></parent>
		<child link="tool0"></child>
	</joint>
	<joint name="fts_fix" type="fixed">
		<origin rpy="0.0 0 -1.57" xyz="0.035 0 0.0"></origin>
		<parent link="ee_link"></parent>
		<child link="fts_robotside"></child>
	</joint>
	<joint name="measurment_joint" type="fixed">
		<origin rpy="0 0 0" xyz="0 0 0.01625"></origin>
		<parent link="fts_robotside"></parent>
		<child link="robotiq_force_torque_frame_id"></child>
	</joint>
	<joint name="toolside_joint" type="fixed">
		<origin rpy="0 0 0" xyz="0 0 0.0375"></origin>
		<parent link="fts_robotside"></parent>
		<child link="fts_toolside"></child>
	</joint>
	<joint name="robotiq_85_base_joint" type="fixed">
		<parent link="fts_toolside"></parent>
		<child link="robotiq_85_base_link"></child>
		<origin rpy="-1.57 0.0 0.0" xyz="0.0 0.0 -0.037"></origin>
	</joint>
	<joint name="robotiq_85_left_knuckle_joint" type="fixed">
		<origin xyz="0.0306011444260539 0 0.0627920162695395" rpy="0 0 0"></origin>
		<parent link="robotiq_85_base_link"></parent>
		<child link="robotiq_85_left_knuckle_link"></child>
		<axis xyz="0 -1 0"></axis>
	</joint>
	<joint name="robotiq_85_left_finger_joint" type="fixed">
		<origin xyz="0.0316910442266543 0 -0.00193396375724605" rpy="0 0 0"></origin>
		<parent link="robotiq_85_left_knuckle_link"></parent>
		<child link="robotiq_85_left_finger_link"></child>
		<axis xyz="0 -1 0"></axis>
	</joint>
	<joint name="robotiq_85_left_inner_knuckle_joint" type="fixed">
		<origin xyz="0.0127000000001501 0 0.0693074999999639" rpy="0 0 0"></origin>
		<parent link="robotiq_85_base_link"></parent>
		<child link="robotiq_85_left_inner_knuckle_link"></child>
		<axis xyz="0 -1 0"></axis>
	</joint>
	<joint name="robotiq_85_left_finger_tip_joint" type="fixed">
		<origin xyz="0.034585310861294 0 0.0454970193817975" rpy="0 0 0"></origin>
		<parent link="robotiq_85_left_inner_knuckle_link"></parent>
		<child link="robotiq_85_left_finger_tip_link"></child>
		<axis xyz="0 -1 0"></axis>
	</joint>
	<joint name="robotiq_85_right_inner_knuckle_joint" type="fixed">
		<origin xyz="-0.0126999999998499 0 0.0693075000000361" rpy="0 0 3.14159265358979"></origin>
		<parent link="robotiq_85_base_link"></parent>
		<child link="robotiq_85_right_inner_knuckle_link"></child>
		<axis xyz="0 1 0"></axis>
	</joint>
	<joint name="robotiq_85_right_finger_tip_joint" type="fixed">
		<origin xyz="0.0341060475457406 0 0.0458573878541688" rpy="0 0 0"></origin>
		<parent link="robotiq_85_right_inner_knuckle_link"></parent>
		<child link="robotiq_85_right_finger_tip_link"></child>
		<axis xyz="0 1 0"></axis>
	</joint>
	<joint name="robotiq_85_right_knuckle_joint" type="fixed">
		<origin xyz="-0.0306011444258893 0 0.0627920162695395" rpy="0 0 3.14159265358979"></origin>
		<parent link="robotiq_85_base_link"></parent>
		<child link="robotiq_85_right_knuckle_link"></child>
		<axis xyz="0 1 0"></axis>
	</joint>
	<joint name="robotiq_85_right_finger_joint" type="fixed">
		<origin xyz="0.0317095909367246 0 -0.0016013564954687" rpy="0 0 0"></origin>
		<parent link="robotiq_85_right_knuckle_link"></parent>
		<child link="robotiq_85_right_finger_link"></child>
		<axis xyz="0 1 0"></axis>
	</joint>
</robot>